Workbook

Sheet Student Data
A1: StudentID | B1: StudentName | C1: Gender | D1: Class | E1: Department | F1: Semester | G1: AttendancePct | H1: AssignmentScore | I1: MidtermScore | J1: FinalExamScore | K1: GPA
A2: S001 | B2: Student 1 | C2: Female | D2: Final | E2: Computer Science | F2: 2 | G2: 77 | H2: 84 | I2: 50 | J2: 46 | K2: 6
A3: S002 | B3: Student 2 | C3: Male | D3: TY | E3: Electronics | F3: 6 | G3: 66 | H3: 74 | I3: 95 | J3: 73 | K3: 8.07
A4: S003 | B4: Student 3 | C4: Male | D4: FY | E4: Arts | F4: 7 | G4: 89 | H4: 68 | I4: 83 | J4: 66 | K4: 7.23
A5: S004 | B5: Student 4 | C5: Female | D5: FY | E5: Arts | F5: 6 | G5: 94 | H5: 80 | I5: 58 | J5: 92 | K5: 7.67
A6: S005 | B6: Student 5 | C6: Female | D6: TY | E6: Arts | F6: 6 | G6: 88 | H6: 70 | I6: 68 | J6: 41 | K6: 5.97
A7: S006 | B7: Student 6 | C7: Female | D7: Final | E7: Arts | F7: 3 | G7: 93 | H7: 68 | I7: 95 | J7: 51 | K7: 7.13
A8: S007 | B8: Student 7 | C8: Female | D8: Final | E8: Computer Science | F8: 4 | G8: 65 | H8: 77 | I8: 68 | J8: 100 | K8: 8.17
A9: S008 | B9: Student 8 | C9: Male | D9: TY | E9: Electronics | F9: 4 | G9: 70 | H9: 89 | I9: 48 | J9: 88 | K9: 7.5
A10: S009 | B10: Student 9 | C10: Male | D10: Final | E10: Computer Science | F10: 6 | G10: 67 | H10: 52 | I10: 86 | J10: 51 | K10: 6.3
A11: S010 | B11: Student 10 | C11: Male | D11: Final | E11: Commerce | F11: 5 | G11: 62 | H11: 65 | I11: 77 | J11: 98 | K11: 8
A12: S011 | B12: Student 11 | C12: Male | D12: TY | E12: Arts | F12: 6 | G12: 86 | H12: 80 | I12: 91 | J12: 91 | K12: 8.73
A13: S012 | B13: Student 12 | C13: Male | D13: TY | E13: Computer Science | F13: 5 | G13: 100 | H13: 83 | I13: 97 | J13: 73 | K13: 8.43
... A201: S200 | B201: Student 200 | C201: Female | D201: SY | E201: Electronics | F201: 1 | G201: 82 | H201: 74 | I201: 98 | J201: 59 | K201: 7.7

Sheet Summary
A1: KEY PERFORMANCE INDICATORS | E1: SEMESTER GPA TREND | H1: StudentID | I1: Attendance% | J1: GPA
A2: Total Students | B2: =COUNTA('Student Data'!A2:A201) -> 200 | F2: Avg GPA | H2: S001 | I2: 77 | J2: 6
A3: Avg GPA | B3: =AVERAGE('Student Data'!K2:K201) -> 7.14145 | E3: Semester 1 | F3: =AVERAGEIF('Student Data'!F2:F201,1,'Student Data'!K2:K201) -> 7.1774074 | H3: S002 | I3: 66 | J3: 8.07
A4: Avg Attendance % | B4: =AVERAGE('Student Data'!G2:G201) -> 80.365 | E4: Semester 2 | F4: =AVERAGEIF('Student Data'!F2:F201,2,'Student Data'!K2:K201) -> 7.1891304 | H4: S003 | I4: 89 | J4: 7.23
A5: Pass Rate % | B5: =COUNTIF('Student Data'!K2:K201,">="&5)/COUNTA('Student Data'!A2:A201)*100 -> 100 | E5: Semester 3 | F5: =AVERAGEIF('Student Data'!F2:F201,3,'Student Data'!K2:K201) -> 7.0385185 | H5: S004 | I5: 94 | J5: 7.67
E6: Semester 4 | F6: =AVERAGEIF('Student Data'!F2:F201,4,'Student Data'!K2:K201) -> 6.9253571 | H6: S005 | I6: 88 | J6: 5.97
E7: Semester 5 | F7: =AVERAGEIF('Student Data'!F2:F201,5,'Student Data'!K2:K201) -> 7.2552941 | H7: S006 | I7: 93 | J7: 7.13
A8: AVG GPA BY DEPARTMENT | E8: Semester 6 | F8: =AVERAGEIF('Student Data'!F2:F201,6,'Student Data'!K2:K201) -> 7.3831818 | H8: S007 | I8: 65 | J8: 8.17
B9: Avg GPA | C9: Student Count | E9: Semester 7 | F9: =AVERAGEIF('Student Data'!F2:F201,7,'Student Data'!K2:K201) -> 7.12625 | H9: S008 | I9: 70 | J9: 7.5
A10: Arts | B10: =AVERAGEIF('Student Data'!E2:E201,A10,'Student Data'!K2:K201) -> 7.24 | C10: =COUNTIF('Student Data'!E2:E201,A10) -> 44 | E10: Semester 8 | F10: =AVERAGEIF('Student Data'!F2:F201,8,'Student Data'!K2:K201) -> 7.004 | H10: S009 | I10: 67 | J10: 6.3
A11: Commerce | B11: =AVERAGEIF('Student Data'!E2:E201,A11,'Student Data'!K2:K201) -> 7.1745 | C11: =COUNTIF('Student Data'!E2:E201,A11) -> 40 | H11: S010 | I11: 62 | J11: 8
A12: Computer Science | B12: =AVERAGEIF('Student Data'!E2:E201,A12,'Student Data'!K2:K201) -> 7.1015556 | C12: =COUNTIF('Student Data'!E2:E201,A12) -> 45 | E12: GENDER GPA COMPARISON | H12: S011 | I12: 86 | J12: 8.73
A13: Electronics | B13: =AVERAGEIF('Student Data'!E2:E201,A13,'Student Data'!K2:K201) -> 7.1162857 | C13: =COUNTIF('Student Data'!E2:E201,A13) -> 35 | F13: Avg GPA | H13: S012 | I13: 100 | J13: 8.43
A14: Mechanical | B14: =AVERAGEIF('Student Data'!E2:E201,A14,'Student Data'!K2:K201) -> 7.0586111 | C14: =COUNTIF('Student Data'!E2:E201,A14) -> 36 | E14: Female | F14: =AVERAGEIF('Student Data'!C2:C201,E14,'Student Data'!K2:K201) -> 7.0351515 | H14: S013 | I14: 69 | J14: 7.77
E15: Male | F15: =AVERAGEIF('Student Data'!C2:C201,E15,'Student Data'!K2:K201) -> 7.2456436 | H15: S014 | I15: 70 | J15: 5
H16: S015 | I16: 61 | J16: 6.43
A17: TOP 10 STUDENTS BY GPA | H17: S016 | I17: 96 | J17: 8.43
A18: Student Name | B18: Department | C18: Class | D18: GPA | H18: S017 | I18: 94 | J18: 6.93
A19: Student 36 | B19: Arts | C19: Final | D19: 9.43 | H19: S018 | I19: 80 | J19: 5.6
A20: Student 77 | B20: Electronics | C20: FY | D20: 9.3 | H20: S019 | I20: 88 | J20: 7.27
A21: Student 140 | B21: Computer Science | C21: SY | D21: 9.17 | H21: S020 | I21: 98 | J21: 8.8
A22: Student 90 | B22: Mechanical | C22: FY | D22: 9.1 | H22: S021 | I22: 65 | J22: 5.93
A23: Student 92 | B23: Arts | C23: SY | D23: 9.1 | H23: S022 | I23: 86 | J23: 5.7
A24: Student 192 | B24: Arts | C24: Final | D24: 9.03 | H24: S023 | I24: 88 | J24: 8.1
A25: Student 103 | B25: Electronics | C25: Final | D25: 8.97 | H25: S024 | I25: 97 | J25: 7.83
A26: Student 20 | B26: Mechanical | C26: Final | D26: 8.8 | H26: S025 | I26: 100 | J26: 8.27
A27: Student 163 | B27: Commerce | C27: TY | D27: 8.8 | H27: S026 | I27: 75 | J27: 6
A28: Student 53 | B28: Arts | C28: TY | D28: 8.77 | H28: S027 | I28: 78 | J28: 7
H29: S028 | I29: 89 | J29: 6.7
H30: S029 | I30: 88 | J30: 6.9
H31: S030 | I31: 76 | J31: 6.6
H32: S031 | I32: 92 | J32: 7.03
H33: S032 | I33: 82 | J33: 7.8
H34: S033 | I34: 78 | J34: 7.37
H35: S034 | I35: 83 | J35: 6.13
H36: S035 | I36: 74 | J36: 6.23
H37: S036 | I37: 90 | J37: 9.43
H38: S037 | I38: 84 | J38: 5.77
H39: S038 | I39: 60 | J39: 8.03
H40: S039 | I40: 85 | J40: 8.17
...

Sheet Dashboard
B1: 🎓 ACADEMIC PERFORMANCE DASHBOARD
B6: =Summary!B2 -> 200 | H6: =Summary!B3 -> 7.14145 | N6: =Summary!B4 -> 80.365 | T6: =Summary!B5 -> 100
B8: 📚 Total Students | H8: ⭐ Average GPA | N8: 📅 Avg Attendance | T8: ✅ Pass Rate
V32: TOP 10 STUDENTS
V33: # | W33: Name | X33: Department | Y33: Class | Z33: GPA
V34: 🥇1 | W34: Student 36 | X34: Arts | Y34: Final | Z34: 9.43
V35: 🥈2 | W35: Student 77 | X35: Electronics | Y35: FY | Z35: 9.3
V36: 🥉3 | W36: Student 140 | X36: Computer Science | Y36: SY | Z36: 9.17
V37: 4 | W37: Student 90 | X37: Mechanical | Y37: FY | Z37: 9.1
V38: 5 | W38: Student 92 | X38: Arts | Y38: SY | Z38: 9.1
V39: 6 | W39: Student 192 | X39: Arts | Y39: Final | Z39: 9.03
V40: 7 | W40: Student 103 | X40: Electronics | Y40: Final | Z40: 8.97
V41: 8 | W41: Student 20 | X41: Mechanical | Y41: Final | Z41: 8.8
V42: 9 | W42: Student 163 | X42: Commerce | Y42: TY | Z42: 8.8
V43: 10 | W43: Student 53 | X43: Arts | Y43: TY | Z43: 8.77
